Workbook

Sheet Line Ratings (2)
E2: FAC-008-3 Transmission Lines | I2: OPCO: PSC | L2: VALIDATION STATUS: VALID | R2: OWNERSHIP: Jointly Owned,Xcel Owned
I3: BES: Y | L3: LIFE CYCLE STATUS: AS BUILT
B5: FACILITY DESIGNATION | C5: LINE NAME | D5: FROM SUB | E5: FROM SUB OWNER | F5: TO SUB | G5: TO SUB OWNER | H5: FROM PSSE | I5: TO PSSE | J5: FACILITY OWNERSHIP | K5: EQUIP NAME | L5: EQUIP TYPE | M5: EQUIP LOCATION | N5: SN (AMPS) | O5: SE (AMPS) | P5: WN (AMPS) | Q5: WE (AMPS) | R5: SN (MVA) | S5: SE (MVA) | T5: WN (MVA) | U5: WE (MVA) | V5: COMMENTS
B6: MTHR-HAYD-138.0-1 | C6: 3003 | D6: MT. HARRIS SUBSTATION | E6: XCEL | F6: HAYDEN (WAPA) | G6: FOREIGN | H6: 70525 | I6: 79038 | J6: Xcel Owned | K6: MTHR-HAYD-138.0-1 | L6: FACILITY | N6: 301 | O6: 301 | P6: 301 | Q6: 301 | R6: 72 | S6: 72 | T6: 72 | U6: 72
B7: MTHR-HAYD-138.0-1 | C7: 3003 | D7: MT. HARRIS SUBSTATION | E7: XCEL | F7: HAYDEN (WAPA) | G7: FOREIGN | H7: 70525 | I7: 79038 | J7: Xcel Owned | K7: Foreign Ratings | L7: Foreign Ratings | M7: HAYD | N7: 301 | O7: 301 | P7: 301 | Q7: 301 | R7: 72 | S7: 72 | T7: 72 | U7: 72
B8: UTER-RIFL-230.0-1 | C8: 3007 | D8: RIFLE UTE 230/345KV SUBSTATION | E8: XCEL | F8: RIFLE (WAPA) | G8: FOREIGN | H8: 79057 | I8: 79059 | J8: Jointly Owned | K8: UTER-RIFL-230.0-1 | L8: FACILITY | N8: 1200 | O8: 1200 | P8: 1200 | Q8: 1200 | R8: 478 | S8: 478 | T8: 478 | U8: 478
B9: UTER-RIFL-230.0-1 | C9: 3007 | D9: RIFLE UTE 230/345KV SUBSTATION | E9: XCEL | F9: RIFLE (WAPA) | G9: FOREIGN | H9: 79057 | I9: 79059 | J9: Jointly Owned | K9: Foreign Ratings | L9: Foreign Ratings | M9: RIFL | N9: 1200 | O9: 1200 | P9: 1200 | Q9: 1200 | R9: 478 | S9: 478 | T9: 478 | U9: 478
B10: COLL-UTER-138.0-1 | C10: 3014 | D10: COLLBRAN SUBSTATION | E10: XCEL | F10: RIFLE UTE 230/345KV SUBSTATION | G10: XCEL | H10: 79047 | I10: 79056 | J10: Jointly Owned | K10: COLL-UTER-138.0-1 | L10: FACILITY | N10: 300 | O10: 300 | P10: 300 | Q10: 300 | R10: 72 | S10: 72 | T10: 72 | U10: 72
B11: COLL-UTER-138.0-1 | C11: 3014 | D11: COLLBRAN SUBSTATION | E11: XCEL | F11: RIFLE UTE 230/345KV SUBSTATION | G11: XCEL | H11: 79047 | I11: 79056 | J11: Jointly Owned | K11: C821 135Y | L11: CURRENT_TRANSFORMER | M11: COLL | N11: 300 | O11: 300 | P11: 300 | Q11: 300 | R11: 72 | S11: 72 | T11: 72 | U11: 72
B12: COLL-UTER-138.0-1 | C12: 3014 | D12: COLLBRAN SUBSTATION | E12: XCEL | F12: RIFLE UTE 230/345KV SUBSTATION | G12: XCEL | H12: 79047 | I12: 79056 | J12: Jointly Owned | K12: C821 KWH IN/OUT | L12: SECONDARY_CURRENT_LIMITATION | M12: COLL | N12: 300 | O12: 300 | P12: 300 | Q12: 300 | R12: 72 | S12: 72 | T12: 72 | U12: 72
B13: UTEG-COLL-138.0-1 | C13: 3015 | D13: UTE GRAND JUNCTION SUBSTATION | E13: XCEL | F13: COLLBRAN SUBSTATION | G13: XCEL | H13: 79035 | I13: 79047 | J13: Xcel Owned | K13: UTEG-COLL-138.0-1 | L13: FACILITY | N13: 400 | O13: 400 | P13: 400 | Q13: 400 | R13: 96 | S13: 96 | T13: 96 | U13: 96
B14: UTEG-COLL-138.0-1 | C14: 3015 | D14: UTE GRAND JUNCTION SUBSTATION | E14: XCEL | F14: COLLBRAN SUBSTATION | G14: XCEL | H14: 79035 | I14: 79047 | J14: Xcel Owned | K14: C841 135Y | L14: CURRENT_TRANSFORMER | M14: COLL | N14: 400 | O14: 400 | P14: 400 | Q14: 400 | R14: 96 | S14: 96 | T14: 96 | U14: 96
B15: UTEG-COLL-138.0-1 | C15: 3015 | D15: UTE GRAND JUNCTION SUBSTATION | E15: XCEL | F15: COLLBRAN SUBSTATION | G15: XCEL | H15: 79035 | I15: 79047 | J15: Xcel Owned | K15: C841 135X | L15: CURRENT_TRANSFORMER | M15: COLL | N15: 400 | O15: 400 | P15: 400 | Q15: 400 | R15: 96 | S15: 96 | T15: 96 | U15: 96
B16: CABI-LOOK-230.0-1 | C16: 5003 | D16: CABIN CREEK HYDRO SUBSTATION | E16: XCEL | F16: LOOKOUT SUBSTATION | G16: XCEL | H16: 70072 | I16: 70266 | J16: Xcel Owned | K16: CABI-LOOK-230.0-1 | L16: FACILITY | N16: 1200 | O16: 1200 | P16: 1200 | Q16: 1200 | R16: 478 | S16: 478 | T16: 478 | U16: 478
B17: CABI-LOOK-230.0-1 | C17: 5003 | D17: CABIN CREEK HYDRO SUBSTATION | E17: XCEL | F17: LOOKOUT SUBSTATION | G17: XCEL | H17: 70072 | I17: 70266 | J17: Xcel Owned | K17: 5003 METER VAR | L17: SECONDARY_CURRENT_LIMITATION | M17: LOOK | N17: 1200 | O17: 1200 | P17: 1200 | Q17: 1200 | R17: 478 | S17: 478 | T17: 478 | U17: 478
B18: CABI-LOOK-230.0-1 | C18: 5003 | D18: CABIN CREEK HYDRO SUBSTATION | E18: XCEL | F18: LOOKOUT SUBSTATION | G18: XCEL | H18: 70072 | I18: 70266 | J18: Xcel Owned | K18: 5003 METER VAR | L18: SECONDARY_CURRENT_LIMITATION | M18: CABI | N18: 1200 | O18: 1200 | P18: 1200 | Q18: 1200 | R18: 478 | S18: 478 | T18: 478 | U18: 478
B19: CABI-LOOK-230.0-1 | C19: 5003 | D19: CABIN CREEK HYDRO SUBSTATION | E19: XCEL | F19: LOOKOUT SUBSTATION | G19: XCEL | H19: 70072 | I19: 70266 | J19: Xcel Owned | K19: 5003 METER W | L19: SECONDARY_CURRENT_LIMITATION | M19: CABI | N19: 1200 | O19: 1200 | P19: 1200 | Q19: 1200 | R19: 478 | S19: 478 | T19: 478 | U19: 478
B20: CABI-LOOK-230.0-1 | C20: 5003 | D20: CABIN CREEK HYDRO SUBSTATION | E20: XCEL | F20: LOOKOUT SUBSTATION | G20: XCEL | H20: 70072 | I20: 70266 | J20: Xcel Owned | L20: LINE_TRAP | M20: LOOK | N20: 1200 | O20: 1200 | P20: 1248 | Q20: 1248 | R20: 478 | S20: 478 | T20: 497 | U20: 497
B21: CABI-IDAH-230.0-1 | C21: 5005 | D21: CABIN CREEK HYDRO SUBSTATION | E21: XCEL | F21: IDAHO SPRINGS SUBSTATION | G21: XCEL | H21: 70072 | I21: 70237 | J21: Xcel Owned | K21: CABI-IDAH-230.0-1 | L21: FACILITY | N21: 1188 | O21: 1394 | P21: 1422 | Q21: 1583 | R21: 473 | S21: 555 | T21: 567 | U21: 631
B22: CABI-IDAH-230.0-1 | C22: 5005 | D22: CABIN CREEK HYDRO SUBSTATION | E22: XCEL | F22: IDAHO SPRINGS SUBSTATION | G22: XCEL | H22: 70072 | I22: 70237 | J22: Xcel Owned | K22: Narcissus | L22: BUSBAR_SECTION | M22: IDAH | N22: 1188 | O22: 1394 | P22: 1422 | Q22: 1590 | R22: 473 | S22: 555 | T22: 567 | U22: 633
B23: CABI-IDAH-230.0-1 | C23: 5005 | D23: CABIN CREEK HYDRO SUBSTATION | E23: XCEL | F23: IDAHO SPRINGS SUBSTATION | G23: XCEL | H23: 70072 | I23: 70237 | J23: Xcel Owned | K23: CABI-IDAH-230.0-1 | L23: Transmission Line | M23: 5005 | N23: 1284 | O23: 1413 | P23: 1439 | Q23: 1583 | R23: 512 | S23: 563 | T23: 573 | U23: 631
B24: IDAH-LOOK-230.0-1 | C24: 5005 | D24: IDAHO SPRINGS SUBSTATION | E24: XCEL | F24: LOOKOUT SUBSTATION | G24: XCEL | H24: 70237 | I24: 70266 | J24: Xcel Owned | K24: IDAH-LOOK-230.0-1 | L24: FACILITY | N24: 1188 | O24: 1200 | P24: 1200 | Q24: 1200 | R24: 473 | S24: 478 | T24: 478 | U24: 478
B25: IDAH-LOOK-230.0-1 | C25: 5005 | D25: IDAHO SPRINGS SUBSTATION | E25: XCEL | F25: LOOKOUT SUBSTATION | G25: XCEL | H25: 70237 | I25: 70266 | J25: Xcel Owned | K25: Narcissus | L25: BUSBAR_SECTION | M25: IDAH | N25: 1188 | O25: 1394 | P25: 1422 | Q25: 1590 | R25: 473 | S25: 555 | T25: 567 | U25: 633
B26: IDAH-LOOK-230.0-1 | C26: 5005 | D26: IDAHO SPRINGS SUBSTATION | E26: XCEL | F26: LOOKOUT SUBSTATION | G26: XCEL | H26: 70237 | I26: 70266 | J26: Xcel Owned | K26: 5005 METER VAR | L26: SECONDARY_CURRENT_LIMITATION | M26: LOOK | N26: 1200 | O26: 1200 | P26: 1200 | Q26: 1200 | R26: 478 | S26: 478 | T26: 478 | U26: 478
B27: IDAH-LOOK-230.0-1 | C27: 5005 | D27: IDAHO SPRINGS SUBSTATION | E27: XCEL | F27: LOOKOUT SUBSTATION | G27: XCEL | H27: 70237 | I27: 70266 | J27: Xcel Owned | L27: LINE_TRAP | M27: LOOK | N27: 1200 | O27: 1200 | P27: 1248 | Q27: 1248 | R27: 478 | S27: 478 | T27: 497 | U27: 497
B28: CABI-DILL-230.0-1 | C28: 5007 | D28: CABIN CREEK HYDRO SUBSTATION | E28: XCEL | F28: DILLON SUBSTATION | G28: XCEL | H28: 70072 | I28: 70156 | J28: Xcel Owned | K28: CABI-DILL-230.0-1 | L28: FACILITY | N28: 1591 | O28: 1591 | P28: 1664 | Q28: 1664 | R28: 634 | S28: 634 | T28: 663 | U28: 663
B29: CABI-DILL-230.0-1 | C29: 5007 | D29: CABIN CREEK HYDRO SUBSTATION | E29: XCEL | F29: DILLON SUBSTATION | G29: XCEL | H29: 70072 | I29: 70156 | J29: Xcel Owned | K29: CABI-DILL-230.0-1 | L29: Transmission Line | M29: 5007 | N29: 1591 | O29: 1591 | P29: 1891 | Q29: 1891 | R29: 634 | S29: 634 | T29: 753 | U29: 753
B30: CABI-DILL-230.0-1 | C30: 5007 | D30: CABIN CREEK HYDRO SUBSTATION | E30: XCEL | F30: DILLON SUBSTATION | G30: XCEL | H30: 70072 | I30: 70156 | J30: Xcel Owned | L30: LINE_TRAP | M30: DILL | N30: 1600 | O30: 1600 | P30: 1664 | Q30: 1664 | R30: 637 | S30: 637 | T30: 663 | U30: 663
B31: RUSS-CHER-230.0-1 | C31: 5021 | D31: RUSSELL SUBSTATION | E31: XCEL | F31: CHEROKEE SWITCHYARD SUBSTATION | G31: XCEL | H31: 70369 | I31: 70107 | J31: Xcel Owned | K31: RUSS-CHER-230.0-1 | L31: FACILITY | N31: 944 | O31: 1038 | P31: 1152 | Q31: 1267 | R31: 376 | S31: 414 | T31: 459 | U31: 505
B32: RUSS-CHER-230.0-1 | C32: 5021 | D32: RUSSELL SUBSTATION | E32: XCEL | F32: CHEROKEE SWITCHYARD SUBSTATION | G32: XCEL | H32: 70369 | I32: 70107 | J32: Xcel Owned | K32: RUSS-CHER-230.0-1 | L32: Transmission Line | M32: 5021 | N32: 944 | O32: 1038 | P32: 1152 | Q32: 1267 | R32: 376 | S32: 414 | T32: 459 | U32: 505
B33: RUSS-RIDG-230.0-1 | C33: 5021 | D33: RUSSELL SUBSTATION | E33: XCEL | F33: RIDGE SUBSTATION | G33: XCEL | H33: 70369 | I33: 70355 | J33: Xcel Owned | K33: RUSS-RIDG-230.0-1 | L33: FACILITY | N33: 944 | O33: 1038 | P33: 1152 | Q33: 1200 | R33: 376 | S33: 414 | T33: 459 | U33: 478
B34: RUSS-RIDG-230.0-1 | C34: 5021 | D34: RUSSELL SUBSTATION | E34: XCEL | F34: RIDGE SUBSTATION | G34: XCEL | H34: 70369 | I34: 70355 | J34: Xcel Owned | K34: RUSS-RIDG-230.0-1 | L34: Transmission Line | M34: 5021 | N34: 944 | O34: 1038 | P34: 1152 | Q34: 1267 | R34: 376 | S34: 414 | T34: 459 | U34: 505
B35: RUSS-RIDG-230.0-1 | C35: 5021 | D35: RUSSELL SUBSTATION | E35: XCEL | F35: RIDGE SUBSTATION | G35: XCEL | H35: 70369 | I35: 70355 | J35: Xcel Owned | K35: L5021 METER VAR | L35: SECONDARY_CURRENT_LIMITATION | M35: RIDG | N35: 1200 | O35: 1200 | P35: 1200 | Q35: 1200 | R35: 478 | S35: 478 | T35: 478 | U35: 478
B36: CHAT-WATE-230.0-1 | C36: 5023 | D36: CHATFIELD SUBSTATION | E36: XCEL | F36: WATERTON SUBSTATION | G36: XCEL | H36: 70100 | I36: 70464 | J36: Xcel Owned | K36: CHAT-WATE-230.0-1 | L36: FACILITY | N36: 1214 | O36: 1397 | P36: 1447 | Q36: 1592 | R36: 483 | S36: 557 | T36: 576 | U36: 634
B37: CHAT-WATE-230.0-1 | C37: 5023 | D37: CHATFIELD SUBSTATION | E37: XCEL | F37: WATERTON SUBSTATION | G37: XCEL | H37: 70100 | I37: 70464 | J37: Xcel Owned | K37: Narcissus | L37: BUSBAR_SECTION | M37: CHAT | N37: 1214 | O37: 1420 | P37: 1450 | Q37: 1619 | R37: 483 | S37: 566 | T37: 578 | U37: 645
B38: CHAT-WATE-230.0-1 | C38: 5023 | D38: CHATFIELD SUBSTATION | E38: XCEL | F38: WATERTON SUBSTATION | G38: XCEL | H38: 70100 | I38: 70464 | J38: Xcel Owned | K38: CHAT-WATE-230.0-1 | L38: Transmission Line | M38: 5023 | N38: 1270 | O38: 1397 | P38: 1447 | Q38: 1592 | R38: 506 | S38: 557 | T38: 576 | U38: 634
B39: SODA-CHAT-230.0-1 | C39: 5023 | D39: SODA LAKES SUBSTATION | E39: XCEL | F39: CHATFIELD SUBSTATION | G39: XCEL | H39: 70018 | I39: 70100 | J39: Xcel Owned | K39: SODA-CHAT-230.0-1 | L39: FACILITY | N39: 1214 | O39: 1397 | P39: 1447 | Q39: 1592 | R39: 483 | S39: 557 | T39: 576 | U39: 634
B40: SODA-CHAT-230.0-1 | C40: 5023 | D40: SODA LAKES SUBSTATION | E40: XCEL | F40: CHATFIELD SUBSTATION | G40: XCEL | H40: 70018 | I40: 70100 | J40: Xcel Owned | K40: Narcissus | L40: BUSBAR_SECTION | M40: CHAT | N40: 1214 | O40: 1420 | P40: 1450 | Q40: 1619 | R40: 483 | S40: 566 | T40: 578 | U40: 645
B41: SODA-CHAT-230.0-1 | C41: 5023 | D41: SODA LAKES SUBSTATION | E41: XCEL | F41: CHATFIELD SUBSTATION | G41: XCEL | H41: 70018 | I41: 70100 | J41: Xcel Owned | K41: SODA-CHAT-230.0-1 | L41: Transmission Line | M41: 5023 | N41: 1270 | O41: 1397 | P41: 1447 | Q41: 1592 | R41: 506 | S41: 557 | T41: 576 | U41: 634
B42: LOOK-PLEN-230.0-1 | C42: 5025 | D42: LOOKOUT SUBSTATION | E42: XCEL | F42: PLAINS END SWITCHING STATION | G42: XCEL | H42: 70266 | I42: 70570 | J42: Xcel Owned | K42: LOOK-PLEN-230.0-1 | L42: FACILITY | N42: 1166 | O42: 1200 | P42: 1200 | Q42: 1200 | R42: 465 | S42: 478 | T42: 478 | U42: 478
...

Sheet Cover
A6: SUBSTATION / TRANSMISSION FACILITY EQUIPMENT RATINGS FAC-008-5 Revision 2025-02 September, 2025
BN9: Temporary Rating For Bancrroft Outage (Valid Until 11-01-17)
AQ32: e

Sheet Instruction Sheet
BN9: Temporary Rating For Bancrroft Outage (Valid Until 11-01-17)

Sheet Line Ratings
E2: FAC-008-5 Transmission Lines | I2: OPCO: PSC | L2: VALIDATION STATUS: VALID | R2: OWNERSHIP: Jointly Owned,Xcel Owned
I3: BES: Y | L3: LIFE CYCLE STATUS: AS BUILT
B5: FACILITY DESIGNATION | C5: LINE NAME | D5: FROM SUB | E5: FROM SUB OWNER | F5: TO SUB | G5: TO SUB OWNER | H5: FROM PSSE | I5: TO PSSE | J5: FACILITY OWNERSHIP | K5: EQUIP NAME | L5: EQUIP TYPE | M5: EQUIP LOCATION | N5: SN (AMPS) | O5: SE (AMPS) | P5: WN (AMPS) | Q5: WE (AMPS) | R5: SN (MVA) | S5: SE (MVA) | T5: WN (MVA) | U5: WE (MVA) | V5: COMMENTS
B6: ADKO_TP-GILC-115.0-1 | C6: 9494 | D6: ANADARKO TAP | E6: XCEL | F6: GILCREST SUBSTATION | G6: XCEL | H6: 70219 | I6: 70198 | J6: Xcel Owned | K6: ADKO_TP-GILC-115.0-1 | L6: FACILITY | N6: 803 | O6: 883 | P6: 913 | Q6: 1004 | R6: 160 | S6: 176 | T6: 182 | U6: 200
B7: ADKO_TP-GILC-115.0-1 | C7: 9494 | D7: ANADARKO TAP | E7: XCEL | F7: GILCREST SUBSTATION | G7: XCEL | H7: 70219 | I7: 70198 | J7: Xcel Owned | K7: ADKO_TP-GILC-115.0-1 | L7: Transmission Line | M7: 9494 | N7: 803 | O7: 883 | P7: 913 | Q7: 1004 | R7: 160 | S7: 176 | T7: 182 | U7: 200
B8: ADKO_TP-VASQ-115.0-1 | C8: 9494 | D8: ANADARKO TAP | E8: XCEL | F8: VASQUEZ SUBSTATION | G8: XCEL | H8: 70219 | I8: 70450 | J8: Xcel Owned | K8: ADKO_TP-VASQ-115.0-1 | L8: FACILITY | N8: 803 | O8: 883 | P8: 912 | Q8: 1004 | R8: 160 | S8: 176 | T8: 182 | U8: 200
B9: ADKO_TP-VASQ-115.0-1 | C9: 9494 | D9: ANADARKO TAP | E9: XCEL | F9: VASQUEZ SUBSTATION | G9: XCEL | H9: 70219 | I9: 70450 | J9: Xcel Owned | K9: ADKO_TP-VASQ-115.0-1 | L9: Transmission Line | M9: 9494 | N9: 803 | O9: 883 | P9: 912 | Q9: 1004 | R9: 160 | S9: 176 | T9: 182 | U9: 200
B10: ADOB-UINT-230.0-1 | C10: 5555 | D10: ADOBE SUBSTATION | E10: XCEL | F10: UINTAH SUBSTATION | G10: XCEL | H10: 70268 | I10: 70438 | J10: Xcel Owned | K10: ADOB-UINT-230.0-1 | L10: FACILITY | N10: 791 | O10: 791 | P10: 795 | Q10: 795 | R10: 315 | S10: 315 | T10: 317 | U10: 317 | V10: Railroad Documentation
B11: ADOB-UINT-230.0-1 | C11: 5555 | D11: ADOBE SUBSTATION | E11: XCEL | F11: UINTAH SUBSTATION | G11: XCEL | H11: 70268 | I11: 70438 | J11: Xcel Owned | K11: ADOB-UINT-230.0-1 | L11: Transmission Line | M11: 5555 | N11: 791 | O11: 791 | P11: 795 | Q11: 795 | R11: 315 | S11: 315 | T11: 317 | U11: 317
B12: ALLI-KEND-115.0-1 | C12: 8024 | D12: ALLISON SUBSTATION | E12: XCEL | F12: KENDRICK SUBSTATION | G12: XCEL | H12: 70023 | I12: 70242 | J12: Xcel Owned | K12: ALLI-KEND-115.0-1 | L12: FACILITY | N12: 710 | O12: 781 | P12: 710 | Q12: 781 | R12: 141 | S12: 156 | T12: 141 | U12: 156
B13: ALLI-KEND-115.0-1 | C13: 8024 | D13: ALLISON SUBSTATION | E13: XCEL | F13: KENDRICK SUBSTATION | G13: XCEL | H13: 70023 | I13: 70242 | J13: Xcel Owned | K13: ALLI-KEND-115.0-1 | L13: Transmission Line | M13: 8024 | N13: 710 | O13: 781 | P13: 710 | Q13: 781 | R13: 141 | S13: 156 | T13: 141 | U13: 156
B14: ALLI-SODA-115.0-1 | C14: 8024 | D14: ALLISON SUBSTATION | E14: XCEL | F14: SODA LAKES SUBSTATION | G14: XCEL | H14: 70023 | I14: 70400 | J14: Xcel Owned | K14: ALLI-SODA-115.0-1 | L14: FACILITY | N14: 950 | O14: 1045 | P14: 950 | Q14: 1045 | R14: 189 | S14: 208 | T14: 189 | U14: 208
B15: ALLI-SODA-115.0-1 | C15: 8024 | D15: ALLISON SUBSTATION | E15: XCEL | F15: SODA LAKES SUBSTATION | G15: XCEL | H15: 70023 | I15: 70400 | J15: Xcel Owned | K15: ALLI-SODA-115.0-1 | L15: Transmission Line | M15: 8024 | N15: 950 | O15: 1045 | P15: 950 | Q15: 1045 | R15: 189 | S15: 208 | T15: 189 | U15: 208
B16: ALMA-BREC-230.0-1 | C16: 5487 | D16: ALMA SUBSTATION | E16: XCEL | F16: BRECKENRIDGE SUBSTATION | G16: XCEL | H16: 70032 | I16: 70064 | J16: Xcel Owned | K16: ALMA-BREC-230.0-1 | L16: FACILITY | N16: 1783 | O16: 2000 | P16: 2000 | Q16: 2000 | R16: 710 | S16: 797 | T16: 797 | U16: 797
B17: ALMA-BREC-230.0-1 | C17: 5487 | D17: ALMA SUBSTATION | E17: XCEL | F17: BRECKENRIDGE SUBSTATION | G17: XCEL | H17: 70032 | I17: 70064 | J17: Xcel Owned | K17: 2½" (AL 40) | L17: BUSBAR_SECTION | M17: ALMA | N17: 1783 | O17: 2140 | P17: 2174 | Q17: 2462 | R17: 710 | S17: 853 | T17: 866 | U17: 981
B18: ALMA-BREC-230.0-1 | C18: 5487 | D18: ALMA SUBSTATION | E18: XCEL | F18: BRECKENRIDGE SUBSTATION | G18: XCEL | H18: 70032 | I18: 70064 | J18: Xcel Owned | K18: 5487-3 | L18: CIRCUIT_SWITCHER | M18: ALMA | N18: 2000 | O18: 2000 | P18: 2000 | Q18: 2000 | R18: 797 | S18: 797 | T18: 797 | U18: 797
B19: ALMA-MALT-230.0-1 | C19: 5487 | D19: ALMA SUBSTATION | E19: XCEL | F19: MALTA SUBSTATION | G19: XCEL | H19: 70032 | I19: 70274 | J19: Xcel Owned | K19: ALMA-MALT-230.0-1 | L19: FACILITY | N19: 1037 | O19: 1200 | P19: 1200 | Q19: 1200 | R19: 413 | S19: 478 | T19: 478 | U19: 478
B20: ALMA-MALT-230.0-1 | C20: 5487 | D20: ALMA SUBSTATION | E20: XCEL | F20: MALTA SUBSTATION | G20: XCEL | H20: 70032 | I20: 70274 | J20: Xcel Owned | K20: Curlew | L20: BUSBAR_SECTION | M20: MALT | N20: 1037 | O20: 1215 | P20: 1244 | Q20: 1387 | R20: 413 | S20: 484 | T20: 496 | U20: 553
B21: ALMA-MALT-230.0-1 | C21: 5487 | D21: ALMA SUBSTATION | E21: XCEL | F21: MALTA SUBSTATION | G21: XCEL | H21: 70032 | I21: 70274 | J21: Xcel Owned | K21: 5487 135Y | L21: CURRENT_TRANSFORMER | M21: MALT | N21: 1200 | O21: 1200 | P21: 1200 | Q21: 1200 | R21: 478 | S21: 478 | T21: 478 | U21: 478
B22: ALMA-MALT-230.0-1 | C22: 5487 | D22: ALMA SUBSTATION | E22: XCEL | F22: MALTA SUBSTATION | G22: XCEL | H22: 70032 | I22: 70274 | J22: Xcel Owned | K22: 5487 135X | L22: CURRENT_TRANSFORMER | M22: MALT | N22: 1200 | O22: 1200 | P22: 1200 | Q22: 1200 | R22: 478 | S22: 478 | T22: 478 | U22: 478
B23: ALMA-MALT-230.0-1 | C23: 5487 | D23: ALMA SUBSTATION | E23: XCEL | F23: MALTA SUBSTATION | G23: XCEL | H23: 70032 | I23: 70274 | J23: Xcel Owned | K23: 5487 246X | L23: CURRENT_TRANSFORMER | M23: MALT | N23: 1200 | O23: 1200 | P23: 1200 | Q23: 1200 | R23: 478 | S23: 478 | T23: 478 | U23: 478
B24: ALMA-MALT-230.0-1 | C24: 5487 | D24: ALMA SUBSTATION | E24: XCEL | F24: MALTA SUBSTATION | G24: XCEL | H24: 70032 | I24: 70274 | J24: Xcel Owned | K24: 5487 246Y | L24: CURRENT_TRANSFORMER | M24: MALT | N24: 1200 | O24: 1200 | P24: 1200 | Q24: 1200 | R24: 478 | S24: 478 | T24: 478 | U24: 478
B25: ARAP-ARLQ_TP-115.0-1 | C25: 9332 | D25: ARAPAHOE SUBSTATION | E25: XCEL | F25: AIR LIQUIDE TAP | G25: XCEL | H25: 70036 | I25: 70531 | J25: Xcel Owned | K25: ARAP-ARLQ_TP-115.0-1 | L25: FACILITY | N25: 600 | O25: 775 | P25: 743 | Q25: 890 | R25: 120 | S25: 154 | T25: 148 | U25: 177
B26: ARAP-ARLQ_TP-115.0-1 | C26: 9332 | D26: ARAPAHOE SUBSTATION | E26: XCEL | F26: AIR LIQUIDE TAP | G26: XCEL | H26: 70036 | I26: 70531 | J26: Xcel Owned | K26: 9332M | L26: SWITCH | M26: ARAP | N26: 600 | O26: 775 | P26: 743 | Q26: 890 | R26: 120 | S26: 154 | T26: 148 | U26: 177
B27: ARAP-DAKO-230.0-1 | C27: 5623 | D27: ARAPAHOE SUBSTATION | E27: XCEL | F27: DAKOTA SUBSTATION | G27: XCEL | H27: 70038 | I27: 70141 | J27: Xcel Owned | K27: ARAP-DAKO-230.0-1 | L27: FACILITY | N27: 1426 | O27: 1568 | P27: 1625 | Q27: 1787 | R27: 568 | S27: 625 | T27: 647 | U27: 712
B28: ARAP-DAKO-230.0-1 | C28: 5623 | D28: ARAPAHOE SUBSTATION | E28: XCEL | F28: DAKOTA SUBSTATION | G28: XCEL | H28: 70038 | I28: 70141 | J28: Xcel Owned | K28: Narcissus | L28: BUSBAR_SECTION | M28: DAKO | N28: 1426 | O28: 1568 | P28: 1625 | Q28: 1787 | R28: 568 | S28: 625 | T28: 647 | U28: 712
B29: ARAP-DTER-230.0-1 | C29: 5449 | D29: ARAPAHOE SUBSTATION | E29: XCEL | F29: DENVER TERMINAL SUBSTATION | G29: XCEL | H29: 70038 | I29: 70149 | J29: Xcel Owned | K29: ARAP-DTER-230.0-1 | L29: FACILITY | N29: 1444 | O29: 1588 | P29: 1645 | Q29: 1810 | R29: 575 | S29: 633 | T29: 655 | U29: 721
B30: ARAP-DTER-230.0-1 | C30: 5449 | D30: ARAPAHOE SUBSTATION | E30: XCEL | F30: DENVER TERMINAL SUBSTATION | G30: XCEL | H30: 70038 | I30: 70149 | J30: Xcel Owned | K30: ARAP-DTER-230.0-1 | L30: Transmission Line | M30: 5449 | N30: 1444 | O30: 1588 | P30: 1645 | Q30: 1810 | R30: 575 | S30: 633 | T30: 655 | U30: 721
B31: ARAP-ENGL-115.0-1 | C31: 9336 | D31: ARAPAHOE SUBSTATION | E31: XCEL | F31: ENGLEWOOD SUBSTATION | G31: XCEL | H31: 70037 | I31: 70167 | J31: Xcel Owned | K31: ARAP-ENGL-115.0-1 | L31: FACILITY | N31: 799 | O31: 879 | P31: 869 | Q31: 956 | R31: 159 | S31: 175 | T31: 173 | U31: 190
B32: ARAP-ENGL-115.0-1 | C32: 9336 | D32: ARAPAHOE SUBSTATION | E32: XCEL | F32: ENGLEWOOD SUBSTATION | G32: XCEL | H32: 70037 | I32: 70167 | J32: Xcel Owned | K32: Hawk | L32: BUSBAR_SECTION | M32: ARAP | N32: 799 | O32: 879 | P32: 909 | Q32: 999 | R32: 159 | S32: 175 | T32: 181 | U32: 199
B33: ARAP-ENGL-115.0-1 | C33: 9336 | D33: ARAPAHOE SUBSTATION | E33: XCEL | F33: ENGLEWOOD SUBSTATION | G33: XCEL | H33: 70037 | I33: 70167 | J33: Xcel Owned | K33: ARAP-ENGL-115.0-1 | L33: Transmission Line | M33: 9336 | N33: 803 | O33: 883 | P33: 869 | Q33: 956 | R33: 160 | S33: 176 | T33: 173 | U33: 190
B34: ARAP-GREE-230.0-1 | C34: 5709 | D34: ARAPAHOE SUBSTATION | E34: XCEL | F34: GREENWOOD SUBSTATION | G34: XCEL | H34: 70038 | I34: 70189 | J34: Xcel Owned | K34: ARAP-GREE-230.0-1 | L34: FACILITY | N34: 1440 | O34: 1584 | P34: 1642 | Q34: 1806 | R34: 574 | S34: 631 | T34: 654 | U34: 719
B35: ARAP-GREE-230.0-1 | C35: 5709 | D35: ARAPAHOE SUBSTATION | E35: XCEL | F35: GREENWOOD SUBSTATION | G35: XCEL | H35: 70038 | I35: 70189 | J35: Xcel Owned | K35: ARAP-GREE-230.0-1 | L35: Transmission Line | M35: 5709 | N35: 1440 | O35: 1584 | P35: 1642 | Q35: 1806 | R35: 574 | S35: 631 | T35: 654 | U35: 719
B36: ARAP-SANT-230.0-1 | C36: 5107 | D36: ARAPAHOE SUBSTATION | E36: XCEL | F36: SANTA FE SUBSTATION | G36: XCEL | H36: 70038 | I36: 70527 | J36: Xcel Owned | K36: ARAP-SANT-230.0-1 | L36: FACILITY | N36: 1266 | O36: 1393 | P36: 1443 | Q36: 1587 | R36: 504 | S36: 555 | T36: 575 | U36: 632
B37: ARAP-SANT-230.0-1 | C37: 5107 | D37: ARAPAHOE SUBSTATION | E37: XCEL | F37: SANTA FE SUBSTATION | G37: XCEL | H37: 70038 | I37: 70527 | J37: Xcel Owned | K37: ARAP-SANT-230.0-1 | L37: Transmission Line | M37: 5107 | N37: 1266 | O37: 1393 | P37: 1443 | Q37: 1587 | R37: 504 | S37: 555 | T37: 575 | U37: 632
B38: ARAP-SOUT_TP-115.0-1 | C38: 9335 | D38: ARAPAHOE SUBSTATION | E38: XCEL | F38: SOUTH TAP | G38: XCEL | H38: 70037 | I38: 70398 | J38: Xcel Owned | K38: ARAP-SOUT_TP-115.0-1 | L38: FACILITY | N38: 798 | O38: 878 | P38: 908 | Q38: 998 | R38: 159 | S38: 175 | T38: 181 | U38: 199
B39: ARAP-SOUT_TP-115.0-1 | C39: 9335 | D39: ARAPAHOE SUBSTATION | E39: XCEL | F39: SOUTH TAP | G39: XCEL | H39: 70037 | I39: 70398 | J39: Xcel Owned | K39: ARAP-SOUT_TP-115.0-1 | L39: Transmission Line | M39: 9335 | N39: 798 | O39: 878 | P39: 908 | Q39: 998 | R39: 159 | S39: 175 | T39: 181 | U39: 199
B40: ARAP-UNIV-115.0-1 | C40: 9338 | D40: ARAPAHOE SUBSTATION | E40: XCEL | F40: UNIVERSITY SUBSTATION | G40: XCEL | H40: 70036 | I40: 70441 | J40: Xcel Owned | K40: ARAP-UNIV-115.0-1 | L40: FACILITY | N40: 773 | O40: 773 | P40: 773 | Q40: 773 | R40: 154 | S40: 154 | T40: 154 | U40: 154
B41: ARAP-UNIV-115.0-1 | C41: 9338 | D41: ARAPAHOE SUBSTATION | E41: XCEL | F41: UNIVERSITY SUBSTATION | G41: XCEL | H41: 70036 | I41: 70441 | J41: Xcel Owned | K41: ARAP-UNIV-115.0-1 | L41: Transmission Line | M41: 9338 | N41: 773 | O41: 773 | P41: 773 | Q41: 773 | R41: 154 | S41: 154 | T41: 154 | U41: 154
B42: ARGO-CHER-115.0-1 | C42: 9413 | D42: ARGO SUBSTATION | E42: XCEL | F42: CHEROKEE SWITCHYARD SUBSTATION | G42: XCEL | H42: 70039 | I42: 70108 | J42: Xcel Owned | K42: ARGO-CHER-115.0-1 | L42: FACILITY | N42: 1200 | O42: 1427 | P42: 1458 | Q42: 1600 | R42: 239 | S42: 284 | T42: 290 | U42: 319
...

Sheet Manually Rated
E2: FAC-008-5 Transmission Lines | I2: OPCO: PSC | L2: VALIDATION STATUS: VALID | R2: OWNERSHIP: Jointly Owned,Xcel Owned
I3: BES: Y | L3: LIFE CYCLE STATUS: AS BUILT
B5: FACILITY DESIGNATION | C5: LINE NAME | D5: FROM SUB | E5: FROM SUB OWNER | F5: TO SUB | G5: TO SUB OWNER | H5: FROM PSSE | I5: TO PSSE | J5: FACILITY OWNERSHIP | K5: EQUIP NAME | L5: EQUIP TYPE | M5: EQUIP LOCATION | N5: SN (AMPS) | O5: SE (AMPS) | P5: WN (AMPS) | Q5: WE (AMPS) | R5: SN (MVA) | S5: SE (MVA) | T5: WN (MVA) | U5: WE (MVA) | V5: COMMENTS
B6: BEAV-BEVW-115.0-1 | C6: 9409 | D6: BEAVER CREEK EAST SUBSTATION | E6: XCEL | F6: BEAVER CREEK (WAPA) | G6: FOREIGN | J6: Jointly Owned | K6: BEAV-BEVW-115.0-1 | L6: FACILITY | N6: 1889 | O6: 1920 | P6: 1920 | Q6: 1920 | R6: 376 | S6: 382 | T6: 382 | U6: 382 | V6: 115kV BUS TIE
B7: BEAV-BEVW-115.0-1 | C7: 9409 | D7: BEAVER CREEK EAST SUBSTATION | E7: XCEL | F7: BEAVER CREEK (WAPA) | G7: FOREIGN | J7: Jointly Owned | K7: 2-795 ACSR CONDUCTOR | L7: BUSBAR_SECTION | M7: BEAV | N7: 1889 | O7: 2202 | P7: 2250 | Q7: 2505 | R7: 376 | S7: 439 | T7: 439 | U7: 439
B8: BEAV-BEVW-115.0-1 | C8: 9409 | D8: BEAVER CREEK EAST SUBSTATION | E8: XCEL | F8: BEAVER CREEK (WAPA) | G8: FOREIGN | J8: Jointly Owned | K8: 2-795 ACSR CONDUCTOR | L8: BUSBAR_SECTION | M8: BEVW | N8: 1889 | O8: 2202 | P8: 2250 | Q8: 2505 | R8: 376 | S8: 439 | T8: 439 | U8: 439
B9: BEAV-BEVW-115.0-1 | C9: 9409 | D9: BEAVER CREEK EAST SUBSTATION | E9: XCEL | F9: BEAVER CREEK (WAPA) | G9: FOREIGN | J9: Jointly Owned | K9: KD41 21Z3 | L9: SECONDARY_CURRENT_LIMITATION | M9: BEAV | N9: 1920 | O9: 1920 | P9: 1920 | Q9: 1920 | R9: 382 | S9: 382 | T9: 382 | U9: 382
B10: MIDW-115.0-BKR-9641 | C10: 9641-A | D10: MIDWAY NODE A | E10: XCEL | F10: MIDWAY BANK #1 | G10: XCEL | J10: Xcel Owned | K10: MIDW-115.0-BKR-9641 | L10: FACILITY | N10: 400 | O10: 400 | P10: 400 | Q10: 400 | R10: 80 | S10: 80 | T10: 80 | U10: 80
B11: MIDW-115.0-BKR-9641 | C11: 9641-A | D11: MIDWAY NODE A | E11: XCEL | F11: MIDWAY BANK #1 | G11: XCEL | J11: Xcel Owned | K11: Black Hills Relay | L11: SECONDARY_CURRENT_LIMITATION | M11: MIDW | N11: 400 | O11: 400 | P11: 400 | Q11: 400 | R11: 80 | S11: 80 | T11: 80 | U11: 80
B12: WELD-WEDW-230.0-1 | C12: 5223 | D12: WELD | E12: XCEL | F12: WELD (WAPA) | G12: FOREIGN | J12: Jointly Owned | K12: WELD-WEDW-115.0-1 | L12: FACILITY | N12: 2157 | O12: 2400 | P12: 2400 | Q12: 2400 | R12: 859 | S12: 956 | T12: 956 | U12: 956
B13: WELD-WEDW-230.0-1 | C13: 5223 | D13: WELD | E13: XCEL | F13: WELD (WAPA) | G13: FOREIGN | J13: Jointly Owned | K13: 5220 | L13: SWITCH | M13: WELD | N13: 2157 | O13: 2533 | P13: 2472 | Q13: 2761 | R13: 859 | S13: 1009.0755 | T13: 984.77481 | U13: 1099.9042
B14: WELD-WEDW-230.0-1 | C14: 5223 | D14: WELD | E14: XCEL | F14: WELD (WAPA) | G14: FOREIGN | J14: Jointly Owned | K14: 5223 135X | L14: CURRENT_TRANSFORMER | M14: WELD | N14: 2400 | O14: 2400 | P14: 2400 | Q14: 2400 | R14: 956 | S14: 956 | T14: 956 | U14: 956
B15: WELD-WEDW-230.0-1 | C15: 5223 | D15: WELD | E15: XCEL | F15: WELD (WAPA) | G15: FOREIGN | J15: Jointly Owned | K15: 5223 135Y | L15: CURRENT_TRANSFORMER | M15: WELD | N15: 2400 | O15: 2400 | P15: 2400 | Q15: 2400 | R15: 956 | S15: 956 | T15: 956 | U15: 956
B16: WELD-WEDW-230.0-1 | C16: 5223 | D16: WELD | E16: XCEL | F16: WELD (WAPA) | G16: FOREIGN | J16: Jointly Owned | K16: 5223 246X | L16: CURRENT_TRANSFORMER | M16: WELD | N16: 2400 | O16: 2400 | P16: 2400 | Q16: 2400 | R16: 956 | S16: 956 | T16: 956 | U16: 956
B17: WELD-WEDW-230.0-1 | C17: 5223 | D17: WELD | E17: XCEL | F17: WELD (WAPA) | G17: FOREIGN | J17: Jointly Owned | K17: 5223 246Y | L17: CURRENT_TRANSFORMER | M17: WELD | N17: 2400 | O17: 2400 | P17: 2400 | Q17: 2400 | R17: 956 | S17: 956 | T17: 956 | U17: 956
B18: WELD-WEDW-230.0-1 | C18: 5223 | D18: WELD | E18: XCEL | F18: WELD (WAPA) | G18: FOREIGN | J18: Jointly Owned | K18: 5221 135X | L18: CURRENT_TRANSFORMER | M18: WELD | N18: 2400 | O18: 2400 | P18: 2400 | Q18: 2400 | R18: 956 | S18: 956 | T18: 956 | U18: 956
B19: WELD-WEDW-230.0-1 | C19: 5223 | D19: WELD | E19: XCEL | F19: WELD (WAPA) | G19: FOREIGN | J19: Jointly Owned | K19: 5221 135Y | L19: CURRENT_TRANSFORMER | M19: WELD | N19: 2400 | O19: 2400 | P19: 2400 | Q19: 2400 | R19: 956 | S19: 956 | T19: 956 | U19: 956
B20: WELD-WEDW-230.0-1 | C20: 5223 | D20: WELD | E20: XCEL | F20: WELD (WAPA) | G20: FOREIGN | J20: Jointly Owned | K20: 5221 246X | L20: CURRENT_TRANSFORMER | M20: WELD | N20: 2400 | O20: 2400 | P20: 2400 | Q20: 2400 | R20: 956 | S20: 956 | T20: 956 | U20: 956
B21: WELD-WEDW-230.0-1 | C21: 5223 | D21: WELD | E21: XCEL | F21: WELD (WAPA) | G21: FOREIGN | J21: Jointly Owned | K21: 5221 246Y | L21: CURRENT_TRANSFORMER | M21: WELD | N21: 2400 | O21: 2400 | P21: 2400 | Q21: 2400 | R21: 956 | S21: 956 | T21: 956 | U21: 956
B22: WELD-WEDW-230.0-1 | C22: 5223 | D22: WELD | E22: XCEL | F22: WELD (WAPA) | G22: FOREIGN | J22: Jointly Owned | K22: Meter | L22: CURRENT_TRANSFORMER | M22: WELD | N22: 2400 | O22: 2400 | P22: 2400 | Q22: 2400 | R22: 956 | S22: 956 | T22: 956 | U22: 956

Sheet Line Ratings In Construction
E2: FAC-008-5 Transmission Lines | I2: OPCO: PSC | L2: VALIDATION STATUS: VALID | R2: OWNERSHIP: Jointly Owned,Xcel Owned
I3: BES: Y | L3: LIFE CYCLE STATUS: IN CONSTRUCTION
B5: FACILITY DESIGNATION | C5: LINE NAME | D5: FROM SUB | E5: FROM SUB OWNER | F5: TO SUB | G5: TO SUB OWNER | H5: FROM PSSE | I5: TO PSSE | J5: FACILITY OWNERSHIP | K5: EQUIP NAME | L5: EQUIP TYPE | M5: EQUIP LOCATION | N5: SN (AMPS) | O5: SE (AMPS) | P5: WN (AMPS) | Q5: WE (AMPS) | R5: SN (MVA) | S5: SE (MVA) | T5: WN (MVA) | U5: WE (MVA) | V5: COMMENTS
B6: COMA-TUND-345.0-1 | C6: 7015 | D6: COMANCHE SUBSTATION | E6: XCEL | F6: TUNDRA SUBSTATION | G6: XCEL | H6: 70654 | I6: 70653 | J6: Xcel Owned | K6: COMA-TUND-345.0-1 | L6: FACILITY | N6: 2000 | O6: 2000 | P6: 2112 | Q6: 2112 | R6: 1195 | S6: 1195 | T6: 1262 | U6: 1262
B7: COMA-TUND-345.0-1 | C7: 7015 | D7: COMANCHE SUBSTATION | E7: XCEL | F7: TUNDRA SUBSTATION | G7: XCEL | H7: 70654 | I7: 70653 | J7: Xcel Owned | L7: LINE_TRAP | M7: COMA | N7: 2000 | O7: 2000 | P7: 2112 | Q7: 2112 | R7: 1195 | S7: 1195 | T7: 1262 | U7: 1262
B8: DAKO-DTER-230.0-1 | C8: 5623 | D8: DAKOTA SUBSTATION | E8: XCEL | F8: DENVER TERMINAL SUBSTATION | G8: XCEL | H8: 70141 | I8: 70149 | J8: Xcel Owned | K8: DAKO-DTER-230.0-1 | L8: FACILITY | N8: 1220 | O8: 1427 | P8: 1457 | Q8: 1600 | R8: 486 | S8: 568 | T8: 580 | U8: 637
B9: DAKO-DTER-230.0-1 | C9: 5623 | D9: DAKOTA SUBSTATION | E9: XCEL | F9: DENVER TERMINAL SUBSTATION | G9: XCEL | H9: 70141 | I9: 70149 | J9: Xcel Owned | K9: Narcissus | L9: BUSBAR_SECTION | M9: DTER | N9: 1220 | O9: 1427 | P9: 1457 | Q9: 1626 | R9: 486 | S9: 568 | T9: 580 | U9: 648
B10: DAKO-DTER-230.0-1 | C10: 5623 | D10: DAKOTA SUBSTATION | E10: XCEL | F10: DENVER TERMINAL SUBSTATION | G10: XCEL | H10: 70141 | I10: 70149 | J10: Xcel Owned | K10: 5623-1 | L10: BREAKER | M10: DAKO | N10: 1600 | O10: 1600 | P10: 1600 | Q10: 1600 | R10: 637 | S10: 637 | T10: 637 | U10: 637
B11: DANI-PRAI-230.0-2 | C11: 5707 | D11: DANIELS PARK 115 & 230KV SUBSTATION | E11: XCEL | F11: PRAIRIE SUBSTATION | G11: XCEL | H11: 70139 | I11: 70331 | J11: Xcel Owned | K11: DANI-PRAI-230.0-2 | L11: FACILITY | N11: 1445 | O11: 1590 | P11: 1600 | Q11: 1600 | R11: 576 | S11: 633 | T11: 637 | U11: 637
B12: DANI-PRAI-230.0-2 | C12: 5707 | D12: DANIELS PARK 115 & 230KV SUBSTATION | E12: XCEL | F12: PRAIRIE SUBSTATION | G12: XCEL | H12: 70139 | I12: 70331 | J12: Xcel Owned | K12: DANI-PRAI-230.0-2 | L12: Transmission Line | M12: 5707 | N12: 1445 | O12: 1590 | P12: 1648 | Q12: 1813 | R12: 576 | S12: 633 | T12: 657 | U12: 722
B13: DANI-PRAI-230.0-2 | C13: 5707 | D13: DANIELS PARK 115 & 230KV SUBSTATION | E13: XCEL | F13: PRAIRIE SUBSTATION | G13: XCEL | H13: 70139 | I13: 70331 | J13: Xcel Owned | K13: 5707-1 | L13: BREAKER | M13: PRAI | N13: 1600 | O13: 1600 | P13: 1600 | Q13: 1600 | R13: 637 | S13: 637 | T13: 637 | U13: 637
B14: DTER-FEDC_TP-115.0-1 | C14: 9122 | D14: DENVER TERMINAL SUBSTATION | E14: XCEL | F14: FEDERAL CENTER TAP | G14: XCEL | H14: 70144 | I14: 70173 | J14: Xcel Owned | K14: DTER-FEDC_TP-115.0-1 | L14: FACILITY | N14: 1200 | O14: 1200 | P14: 1200 | Q14: 1200 | R14: 239 | S14: 239 | T14: 239 | U14: 239
B15: DTER-FEDC_TP-115.0-1 | C15: 9122 | D15: DENVER TERMINAL SUBSTATION | E15: XCEL | F15: FEDERAL CENTER TAP | G15: XCEL | H15: 70144 | I15: 70173 | J15: Xcel Owned | K15: 9122 246X 67GP | L15: SECONDARY_CURRENT_LIMITATION | M15: DTER | N15: 1200 | O15: 1200 | P15: 1200 | Q15: 1200 | R15: 239 | S15: 239 | T15: 239 | U15: 239
B16: DTER-FEDC_TP-115.0-1 | C16: 9122 | D16: DENVER TERMINAL SUBSTATION | E16: XCEL | F16: FEDERAL CENTER TAP | G16: XCEL | H16: 70144 | I16: 70173 | J16: Xcel Owned | K16: 9122 246X 21ZP | L16: SECONDARY_CURRENT_LIMITATION | M16: DTER | N16: 1200 | O16: 1200 | P16: 1200 | Q16: 1200 | R16: 239 | S16: 239 | T16: 239 | U16: 239
B17: DTER-FEDC_TP-115.0-1 | C17: 9122 | D17: DENVER TERMINAL SUBSTATION | E17: XCEL | F17: FEDERAL CENTER TAP | G17: XCEL | H17: 70144 | I17: 70173 | J17: Xcel Owned | K17: 9122 246Y 21Z2 | L17: SECONDARY_CURRENT_LIMITATION | M17: DTER | N17: 1200 | O17: 1200 | P17: 1200 | Q17: 1200 | R17: 239 | S17: 239 | T17: 239 | U17: 239
B18: DTER-FEDC_TP-115.0-1 | C18: 9122 | D18: DENVER TERMINAL SUBSTATION | E18: XCEL | F18: FEDERAL CENTER TAP | G18: XCEL | H18: 70144 | I18: 70173 | J18: Xcel Owned | K18: 9122 246Y 21Z1 | L18: SECONDARY_CURRENT_LIMITATION | M18: DTER | N18: 1200 | O18: 1200 | P18: 1200 | Q18: 1200 | R18: 239 | S18: 239 | T18: 239 | U18: 239
B19: DTER-FEDC_TP-115.0-1 | C19: 9122 | D19: DENVER TERMINAL SUBSTATION | E19: XCEL | F19: FEDERAL CENTER TAP | G19: XCEL | H19: 70144 | I19: 70173 | J19: Xcel Owned | K19: Curlew | L19: BUSBAR_SECTION | M19: DTER | N19: 1200 | O19: 1392 | P19: 1442 | Q19: 1586 | R19: 239 | S19: 277 | T19: 287 | U19: 316
B20: DTER-FEDC_TP-115.0-1 | C20: 9122 | D20: DENVER TERMINAL SUBSTATION | E20: XCEL | F20: FEDERAL CENTER TAP | G20: XCEL | H20: 70144 | I20: 70173 | J20: Xcel Owned | K20: DTER-FEDC_TP-115.0-1 | L20: Transmission Line | M20: 9122 | N20: 1200 | O20: 1392 | P20: 1442 | Q20: 1586 | R20: 239 | S20: 277 | T20: 287 | U20: 316
B21: DTER-FEDC_TP-115.0-1 | C21: 9122 | D21: DENVER TERMINAL SUBSTATION | E21: XCEL | F21: FEDERAL CENTER TAP | G21: XCEL | H21: 70144 | I21: 70173 | J21: Xcel Owned | K21: 9122L | L21: SWITCH | M21: DTER | N21: 1200 | O21: 1549 | P21: 1486 | Q21: 1780 | R21: 239 | S21: 309 | T21: 296 | U21: 355
B22: DTER-FEDC_TP-115.0-1 | C22: 9122 | D22: DENVER TERMINAL SUBSTATION | E22: XCEL | F22: FEDERAL CENTER TAP | G22: XCEL | H22: 70144 | I22: 70173 | J22: Xcel Owned | K22: 9122M | L22: SWITCH | M22: DTER | N22: 1200 | O22: 1549 | P22: 1486 | Q22: 1780 | R22: 239 | S22: 309 | T22: 296 | U22: 355
B23: DTER-GRAY-115.0-1 | C23: 9008 | D23: DENVER TERMINAL SUBSTATION | E23: XCEL | F23: GRAY STREET SUBSTATION | G23: XCEL | H23: 70148 | I23: 70208 | J23: Xcel Owned | K23: DTER-GRAY-115.0-1 | L23: FACILITY | N23: 1200 | O23: 1200 | P23: 1200 | Q23: 1200 | R23: 239 | S23: 239 | T23: 239 | U23: 239
B24: DTER-GRAY-115.0-1 | C24: 9008 | D24: DENVER TERMINAL SUBSTATION | E24: XCEL | F24: GRAY STREET SUBSTATION | G24: XCEL | H24: 70148 | I24: 70208 | J24: Xcel Owned | K24: 9008_246Y_METER_W | L24: SECONDARY_CURRENT_LIMITATION | M24: GRAY | N24: 1200 | O24: 1200 | P24: 1200 | Q24: 1200 | R24: 239 | S24: 239 | T24: 239 | U24: 239
B25: DTER-GRAY-115.0-1 | C25: 9008 | D25: DENVER TERMINAL SUBSTATION | E25: XCEL | F25: GRAY STREET SUBSTATION | G25: XCEL | H25: 70148 | I25: 70208 | J25: Xcel Owned | K25: 9008_246Y_XDCR_W | L25: SECONDARY_CURRENT_LIMITATION | M25: GRAY | N25: 1200 | O25: 1200 | P25: 1200 | Q25: 1200 | R25: 239 | S25: 239 | T25: 239 | U25: 239
B26: DTER-GRAY-115.0-1 | C26: 9008 | D26: DENVER TERMINAL SUBSTATION | E26: XCEL | F26: GRAY STREET SUBSTATION | G26: XCEL | H26: 70148 | I26: 70208 | J26: Xcel Owned | K26: 9008_246Y_METER_VAR | L26: SECONDARY_CURRENT_LIMITATION | M26: GRAY | N26: 1200 | O26: 1200 | P26: 1200 | Q26: 1200 | R26: 239 | S26: 239 | T26: 239 | U26: 239
B27: DTER-GRAY-115.0-1 | C27: 9008 | D27: DENVER TERMINAL SUBSTATION | E27: XCEL | F27: GRAY STREET SUBSTATION | G27: XCEL | H27: 70148 | I27: 70208 | J27: Xcel Owned | K27: 9008_246Y_METER_AMPSW | L27: SECONDARY_CURRENT_LIMITATION | M27: GRAY | N27: 1200 | O27: 1200 | P27: 1200 | Q27: 1200 | R27: 239 | S27: 239 | T27: 239 | U27: 239
B28: DTER-GRAY-115.0-1 | C28: 9008 | D28: DENVER TERMINAL SUBSTATION | E28: XCEL | F28: GRAY STREET SUBSTATION | G28: XCEL | H28: 70148 | I28: 70208 | J28: Xcel Owned | K28: 9008_135Y_67GS | L28: SECONDARY_CURRENT_LIMITATION | M28: GRAY | N28: 1200 | O28: 1200 | P28: 1200 | Q28: 1200 | R28: 239 | S28: 239 | T28: 239 | U28: 239
B29: DTER-GRAY-115.0-1 | C29: 9008 | D29: DENVER TERMINAL SUBSTATION | E29: XCEL | F29: GRAY STREET SUBSTATION | G29: XCEL | H29: 70148 | I29: 70208 | J29: Xcel Owned | K29: 9008_246Y_XDCR_VAR | L29: SECONDARY_CURRENT_LIMITATION | M29: GRAY | N29: 1200 | O29: 1200 | P29: 1200 | Q29: 1200 | R29: 239 | S29: 239 | T29: 239 | U29: 239
B30: DTER-GRAY-115.0-1 | C30: 9008 | D30: DENVER TERMINAL SUBSTATION | E30: XCEL | F30: GRAY STREET SUBSTATION | G30: XCEL | H30: 70148 | I30: 70208 | J30: Xcel Owned | K30: 9008M | L30: SWITCH | M30: GRAY | N30: 1200 | O30: 1549 | P30: 1486 | Q30: 1780 | R30: 239 | S30: 309 | T30: 296 | U30: 355
B31: DTER-GRAY-115.0-1 | C31: 9008 | D31: DENVER TERMINAL SUBSTATION | E31: XCEL | F31: GRAY STREET SUBSTATION | G31: XCEL | H31: 70148 | I31: 70208 | J31: Xcel Owned | K31: 9008M | L31: SWITCH | M31: DTER | N31: 1200 | O31: 1549 | P31: 1486 | Q31: 1780 | R31: 239 | S31: 309 | T31: 296 | U31: 355
B32: DTER-GRAY-115.0-1 | C32: 9008 | D32: DENVER TERMINAL SUBSTATION | E32: XCEL | F32: GRAY STREET SUBSTATION | G32: XCEL | H32: 70148 | I32: 70208 | J32: Xcel Owned | K32: 9008L | L32: SWITCH | M32: GRAY | N32: 1200 | O32: 1549 | P32: 1486 | Q32: 1780 | R32: 239 | S32: 309 | T32: 296 | U32: 355
B33: DTER-WEST-230.0-1 | C33: 5629 | D33: DENVER TERMINAL SUBSTATION | E33: XCEL | F33: WEST SUBSTATION | G33: XCEL | H33: 70149 | I33: 70480 | J33: Xcel Owned | K33: DTER-WEST-230.0-1 | L33: FACILITY | N33: 1263 | O33: 1389 | P33: 1439 | Q33: 1583 | R33: 503 | S33: 553 | T33: 573 | U33: 631
B34: DTER-WEST-230.0-1 | C34: 5629 | D34: DENVER TERMINAL SUBSTATION | E34: XCEL | F34: WEST SUBSTATION | G34: XCEL | H34: 70149 | I34: 70480 | J34: Xcel Owned | K34: DTER-WEST-230.0-1 | L34: Transmission Line | M34: 5629 | N34: 1263 | O34: 1389 | P34: 1439 | Q34: 1583 | R34: 503 | S34: 553 | T34: 573 | U34: 631
B35: EAST-CHAM-115.0-1 | C35: 9175 | D35: EAST SUBSTATION | E35: XCEL | F35: CHAMBERS SUBSTATION | G35: XCEL | H35: 70162 | I35: 70538 | J35: Xcel Owned | K35: EAST-CHAM-115.0-1 | L35: FACILITY | N35: 798 | O35: 878 | P35: 908 | Q35: 998 | R35: 159 | S35: 175 | T35: 181 | U35: 199
B36: EAST-CHAM-115.0-1 | C36: 9175 | D36: EAST SUBSTATION | E36: XCEL | F36: CHAMBERS SUBSTATION | G36: XCEL | H36: 70162 | I36: 70538 | J36: Xcel Owned | K36: EAST-CHAM-115.0-1 | L36: Transmission Line | M36: 9175 | N36: 798 | O36: 878 | P36: 908 | Q36: 998 | R36: 159 | S36: 175 | T36: 181 | U36: 199
B37: EAST-FITZ-115.0-1 | C37: 9178 | D37: EAST SUBSTATION | E37: XCEL | F37: FITZSIMONS SUBSTATION | G37: XCEL | H37: 70162 | I37: 70537 | J37: Xcel Owned | K37: EAST-FITZ-115.0-1 | L37: FACILITY | N37: 798 | O37: 878 | P37: 908 | Q37: 998 | R37: 159 | S37: 175 | T37: 181 | U37: 199
B38: EAST-FITZ-115.0-1 | C38: 9178 | D38: EAST SUBSTATION | E38: XCEL | F38: FITZSIMONS SUBSTATION | G38: XCEL | H38: 70162 | I38: 70537 | J38: Xcel Owned | K38: EAST-FITZ-115.0-1 | L38: Transmission Line | M38: 9178 | N38: 798 | O38: 878 | P38: 908 | Q38: 998 | R38: 159 | S38: 175 | T38: 181 | U38: 199
B39: EAST-SMOK-115.0-2 | C39: 9866 | D39: EAST SUBSTATION | E39: XCEL | F39: SMOKY HILL SUBSTATION | G39: XCEL | H39: 70171 | I39: 70395 | J39: Xcel Owned | K39: EAST-SMOK-115.0-2 | L39: FACILITY | N39: 794 | O39: 873 | P39: 903 | Q39: 993 | R39: 158 | S39: 174 | T39: 180 | U39: 198
B40: EAST-SMOK-115.0-2 | C40: 9866 | D40: EAST SUBSTATION | E40: XCEL | F40: SMOKY HILL SUBSTATION | G40: XCEL | H40: 70171 | I40: 70395 | J40: Xcel Owned | K40: EAST-SMOK-115.0-2 | L40: Transmission Line | M40: 9866 | N40: 794 | O40: 873 | P40: 903 | Q40: 993 | R40: 158 | S40: 174 | T40: 180 | U40: 198
B41: FLUP-PVAL-115.0-1 | C41: 9499 | D41: FORT LUPTON SUBSTATION | E41: XCEL | F41: PLATTE VALLEY | G41: XCEL | H41: 70090 | I41: 70307 | J41: Xcel Owned | K41: FLUP-PVAL-115.0-1 | L41: FACILITY | N41: 1200 | O41: 1330 | P41: 1377 | Q41: 1515 | R41: 239 | S41: 265 | T41: 274 | U41: 302
B42: FLUP-PVAL-115.0-1 | C42: 9499 | D42: FORT LUPTON SUBSTATION | E42: XCEL | F42: PLATTE VALLEY | G42: XCEL | H42: 70090 | I42: 70307 | J42: Xcel Owned | K42: 9499-5 | L42: SWITCH | M42: PVAL | N42: 1200 | O42: 1549 | P42: 1486 | Q42: 1780 | R42: 239 | S42: 309 | T42: 296 | U42: 355
...

Sheet Removed Line Facilities
E2: FAC-008-5 Transmission Lines | I2: OPCO: PSC | L2: VALIDATION STATUS: VALID | R2: OWNERSHIP: Jointly Owned,Xcel Owned
I3: BES: Y | L3: LIFE CYCLE STATUS: REMOVED
B5: FACILITY DESIGNATION | C5: LINE NAME | D5: DATE OF REMOVAL | E5: COMMENTS
B6: CHER-THTN-115.0-1 | C6: 9548 | D6: 45890 | E6: Metro Water Recovery substation added. Facility replaced by CHER-METO-115.0-1 LN-9548 and METO-THTN-115.0-1 LN-9737.
B7: CHYW-SHOR-345.0-1 | C7: 7199 | D7: 45779 | E7: Goose Creek substation added. Facility replaced by GOOS-SHOR-345.0-1 LN-7199 and CHYW-GOOS-345.0-1 LN-7261.
B8: CLIM-SUMM-115.0-1 | C8: 9188 | D8: 45691 | E8: Facility BES status changed to E1 Radial.
B9: SANT_TP-SANT-230.0-1 | C9: 5107 | D9: 45691 | E9: Sante Fe Tap removed. Facility replaced by ARAP-SANT-230.0-1 LN-5107.

Sheet Transformer Ratings
D2: FAC-008-5 Transformer | H2: OPCO: PSC | M2: VALIDATION STATUS: VALID
H3: BES: Y | M3: LIFE CYCLE STATUS: AS BUILT
B5: FACILITY DESIGNATION | C5: SUBSTATION | D5: HIGH SIDE PSSE | E5: LOWSIDE PSSE | F5: EQUIPMENT NAME | G5: EQUIPMENT TYPE | H5: VOLTAGE (kV) | I5: SN (MVA) | J5: SE8 (MVA) | K5: SE4 (MVA) | L5: SE2 (MVA) | M5: SE30 (MVA) | N5: WN (MVA) | O5: WE8 (MVA) | P5: WE4 (MVA) | Q5: WE2 (MVA) | R5: WE30 (MVA) | S5: COMMENTS
B6: ARAP-TR05-230.0-115.0-13.8-HX | C6: ARAPAHOE SUBSTATION | D6: 70038 | E6: 70036 | F6: ARAP-TR05-230.0-115.0-13.8-HX | G6: FACILITY | I6: 272 | J6: 272 | K6: 312 | L6: 319 | M6: 319 | N6: 299 | O6: 299 | P6: 319 | Q6: 319 | R6: 319
B7: ARAP-TR05-230.0-115.0-13.8-HX | C7: ARAPAHOE SUBSTATION | D7: 70038 | E7: 70036 | F7: TR05 | G7: TRANSFORMER | H7: 115 | I7: 271 | J7: 271 | K7: 312 | L7: 319 | M7: 319 | N7: 299 | O7: 299 | P7: 319 | Q7: 319 | R7: 319
B8: ARAP-TR05-230.0-115.0-13.8-HX | C8: ARAPAHOE SUBSTATION | D8: 70038 | E8: 70036 | F8: TR05 | G8: TRANSFORMER | H8: 230 | I8: 272 | J8: 272 | K8: 312 | L8: 326 | M8: 339 | N8: 299 | O8: 299 | P8: 339 | Q8: 353 | R8: 367
B9: ARAP-TR05-230.0-115.0-13.8-HX | C9: ARAPAHOE SUBSTATION | D9: 70038 | E9: 70036 | F9: TR05_H-SA_MW | G9: SECONDARY_CURRENT_LIMITATION | H9: 230 | I9: 319 | J9: 319 | K9: 319 | L9: 319 | M9: 319 | N9: 319 | O9: 319 | P9: 319 | Q9: 319 | R9: 319
B10: ARAP-TR05-230.0-115.0-13.8-HX | C10: ARAPAHOE SUBSTATION | D10: 70038 | E10: 70036 | F10: TR05_H-SA_MVAR | G10: SECONDARY_CURRENT_LIMITATION | H10: 230 | I10: 319 | J10: 319 | K10: 319 | L10: 319 | M10: 319 | N10: 319 | O10: 319 | P10: 319 | Q10: 319 | R10: 319
B11: ARAP-TR05-230.0-115.0-13.8-HX | C11: ARAPAHOE SUBSTATION | D11: 70038 | E11: 70036 | F11: TR05_H-SA_AMPS | G11: SECONDARY_CURRENT_LIMITATION | H11: 230 | I11: 319 | J11: 319 | K11: 319 | L11: 319 | M11: 319 | N11: 319 | O11: 319 | P11: 319 | Q11: 319 | R11: 319
B12: ARAP-TR05-230.0-115.0-13.8-HX | C12: ARAPAHOE SUBSTATION | D12: 70038 | E12: 70036 | F12: BK05 BCT H-SA | G12: CURRENT_TRANSFORMER | H12: 230 | I12: 319 | J12: 319 | K12: 319 | L12: 319 | M12: 319 | N12: 319 | O12: 319 | P12: 319 | Q12: 319 | R12: 319
B13: BASA-TR01-230.0-115.0-13.8-HX | C13: BASALT SUBSTATION | D13: 79004 | E13: 79003 | F13: BASA-TR01-230.0-115.0-13.8-HX | G13: FACILITY | I13: 114 | J13: 114 | K13: 120 | L13: 120 | M13: 120 | N13: 120 | O13: 120 | P13: 120 | Q13: 120 | R13: 120
B14: BASA-TR01-230.0-115.0-13.8-HX | C14: BASALT SUBSTATION | D14: 79004 | E14: 79003 | F14: TR01 | G14: TRANSFORMER | H14: 230 | I14: 114 | J14: 114 | K14: 120 | L14: 120 | M14: 120 | N14: 120 | O14: 120 | P14: 120 | Q14: 120 | R14: 120
B15: BASA-TR01-230.0-115.0-13.8-HX | C15: BASALT SUBSTATION | D15: 79004 | E15: 79003 | F15: TR01 | G15: TRANSFORMER | H15: 115 | I15: 114 | J15: 114 | K15: 120 | L15: 120 | M15: 120 | N15: 120 | O15: 120 | P15: 120 | Q15: 120 | R15: 120
B16: BASA-TR01-230.0-115.0-13.8-HX | C16: BASALT SUBSTATION | D16: 79004 | E16: 79003 | F16: BK01 X 14 15 16 | G16: CURRENT_TRANSFORMER | H16: 115 | I16: 120 | J16: 120 | K16: 120 | L16: 120 | M16: 120 | N16: 120 | O16: 120 | P16: 120 | Q16: 120 | R16: 120
B17: BASA-TR02-230.0-115.0-13.8-HX | C17: BASALT SUBSTATION | D17: 79004 | E17: 79003 | F17: BASA-TR02-230.0-115.0-13.8-HX | G17: FACILITY | I17: 168 | J17: 168 | K17: 190 | L17: 190 | M17: 190 | N17: 185 | O17: 185 | P17: 190 | Q17: 190 | R17: 190
B18: BASA-TR02-230.0-115.0-13.8-HX | C18: BASALT SUBSTATION | D18: 79004 | E18: 79003 | F18: TR02 | G18: TRANSFORMER | H18: 115 | I18: 168 | J18: 168 | K18: 193 | L18: 202 | M18: 210 | N18: 185 | O18: 185 | P18: 210 | Q18: 218 | R18: 227
B19: BASA-TR02-230.0-115.0-13.8-HX | C19: BASALT SUBSTATION | D19: 79004 | E19: 79003 | F19: TR02 | G19: TRANSFORMER | H19: 230 | I19: 168 | J19: 168 | K19: 193 | L19: 202 | M19: 210 | N19: 185 | O19: 185 | P19: 210 | Q19: 218 | R19: 227
B20: BASA-TR02-230.0-115.0-13.8-HX | C20: BASALT SUBSTATION | D20: 79004 | E20: 79003 | G20: CABLE_TERMINATOR | H20: 115 | I20: 190 | J20: 190 | K20: 190 | L20: 190 | M20: 190 | N20: 190 | O20: 190 | P20: 190 | Q20: 190 | R20: 190
B21: BASA-TR02-230.0-115.0-13.8-HX | C21: BASALT SUBSTATION | D21: 79004 | E21: 79003 | F21: Jessamine | G21: BUSBAR_SECTION | H21: 115 | I21: 190 | J21: 190 | K21: 190 | L21: 190 | M21: 190 | N21: 190 | O21: 190 | P21: 190 | Q21: 190 | R21: 190
B22: BEAV-TR01-230.0-115.0-13.8-HX | C22: BEAVER CREEK EAST SUBSTATION | D22: 70399 | E22: 70397 | F22: BEAV-TR01-230.0-115.0-13.8-HX | G22: FACILITY | I22: 209 | J22: 209 | K22: 239 | L22: 239 | M22: 239 | N22: 239 | O22: 239 | P22: 239 | Q22: 239 | R22: 239
B23: BEAV-TR01-230.0-115.0-13.8-HX | C23: BEAVER CREEK EAST SUBSTATION | D23: 70399 | E23: 70397 | F23: Cardinal | G23: BUSBAR_SECTION | H23: 115 | I23: 209 | J23: 209 | K23: 243 | L23: 243 | M23: 243 | N23: 249 | O23: 249 | P23: 276 | Q23: 276 | R23: 276
B24: BEAV-TR01-230.0-115.0-13.8-HX | C24: BEAVER CREEK EAST SUBSTATION | D24: 70399 | E24: 70397 | F24: TR01 | G24: TRANSFORMER | H24: 115 | I24: 221 | J24: 254 | K24: 265 | L24: 276 | M24: 298 | N24: 243 | O24: 276 | P24: 287 | Q24: 298 | R24: 319
B25: BEAV-TR01-230.0-115.0-13.8-HX | C25: BEAVER CREEK EAST SUBSTATION | D25: 70399 | E25: 70397 | F25: TR01 | G25: TRANSFORMER | H25: 230 | I25: 221 | J25: 254 | K25: 265 | L25: 276 | M25: 298 | N25: 243 | O25: 276 | P25: 287 | Q25: 298 | R25: 319
B26: BEAV-TR01-230.0-115.0-13.8-HX | C26: BEAVER CREEK EAST SUBSTATION | D26: 70399 | E26: 70397 | F26: TR01 X 11 12 13 | G26: CURRENT_TRANSFORMER | H26: 115 | I26: 239 | J26: 239 | K26: 239 | L26: 239 | M26: 239 | N26: 239 | O26: 239 | P26: 239 | Q26: 239 | R26: 239
B27: BEAV-TR01-230.0-115.0-13.8-HX | C27: BEAVER CREEK EAST SUBSTATION | D27: 70399 | E27: 70397 | F27: DG-2 115KV | G27: SECONDARY_CURRENT_LIMITATION | H27: 115 | I27: 239 | J27: 239 | K27: 239 | L27: 239 | M27: 239 | N27: 239 | O27: 239 | P27: 239 | Q27: 239 | R27: 239
B28: BEAV-TR01-230.0-115.0-13.8-HX | C28: BEAVER CREEK EAST SUBSTATION | D28: 70399 | E28: 70397 | F28: TR01 AMP XDCR | G28: SECONDARY_CURRENT_LIMITATION | H28: 115 | I28: 239 | J28: 239 | K28: 239 | L28: 239 | M28: 239 | N28: 239 | O28: 239 | P28: 239 | Q28: 239 | R28: 239
B29: BEAV-TR01-230.0-115.0-13.8-HX | C29: BEAVER CREEK EAST SUBSTATION | D29: 70399 | E29: 70397 | F29: TR01 X 8 9 10 | G29: CURRENT_TRANSFORMER | H29: 115 | I29: 239 | J29: 239 | K29: 239 | L29: 239 | M29: 239 | N29: 239 | O29: 239 | P29: 239 | Q29: 239 | R29: 239
B30: BLUE-TR01-230.0-115.0-13.8-HX | C30: BLUE RIVER SUBSTATION | D30: 70053 | E30: 70052 | F30: BLUE-TR01-230.0-115.0-13.8-HX | G30: FACILITY | I30: 163 | J30: 176 | K30: 196 | L30: 204 | M30: 206 | N30: 180 | O30: 204 | P30: 212 | Q30: 220 | R30: 235
B31: BLUE-TR01-230.0-115.0-13.8-HX | C31: BLUE RIVER SUBSTATION | D31: 70053 | E31: 70052 | F31: TR01 | G31: TRANSFORMER | H31: 230 | I31: 163 | J31: 188 | K31: 196 | L31: 204 | M31: 220 | N31: 180 | O31: 204 | P31: 212 | Q31: 220 | R31: 245
B32: BLUE-TR01-230.0-115.0-13.8-HX | C32: BLUE RIVER SUBSTATION | D32: 70053 | E32: 70052 | F32: TR01 | G32: TRANSFORMER | H32: 115 | I32: 163 | J32: 188 | K32: 196 | L32: 204 | M32: 220 | N32: 180 | O32: 204 | P32: 212 | Q32: 220 | R32: 245
B33: BLUE-TR01-230.0-115.0-13.8-HX | C33: BLUE RIVER SUBSTATION | D33: 70053 | E33: 70052 | F33: Arbutus | G33: BUSBAR_SECTION | H33: 115 | I33: 176 | J33: 176 | K33: 206 | L33: 206 | M33: 206 | N33: 210 | O33: 210 | P33: 235 | Q33: 235 | R33: 235
B34: BOON-TR01-230.0-115.0-13.8-HX | C34: BOONE SUBSTATION | D34: 70061 | E34: 70060 | F34: BOON-TR01-230.0-115.0-13.8-HX | G34: FACILITY | I34: 147 | J34: 147 | K34: 159 | L34: 159 | M34: 159 | N34: 159 | O34: 159 | P34: 159 | Q34: 159 | R34: 159
B35: BOON-TR01-230.0-115.0-13.8-HX | C35: BOONE SUBSTATION | D35: 70061 | E35: 70060 | F35: TR01 | G35: TRANSFORMER | H35: 115 | I35: 147 | J35: 147 | K35: 159 | L35: 159 | M35: 159 | N35: 159 | O35: 159 | P35: 159 | Q35: 159 | R35: 159
B36: BOON-TR01-230.0-115.0-13.8-HX | C36: BOONE SUBSTATION | D36: 70061 | E36: 70060 | F36: TR01 | G36: TRANSFORMER | H36: 230 | I36: 147 | J36: 147 | K36: 169 | L36: 184 | M36: 191 | N36: 176 | O36: 176 | P36: 191 | Q36: 206 | R36: 214
B37: BRIC-TR01-230.0-115.0-15.0-HX | C37: BRICK CENTER | D37: 70545 | E37: 70546 | F37: BRIC-TR01-230.0-115.0-15.0-HX | G37: FACILITY | I37: 226 | J37: 239 | K37: 239 | L37: 239 | M37: 239 | N37: 239 | O37: 239 | P37: 239 | Q37: 239 | R37: 239
B38: BRIC-TR01-230.0-115.0-15.0-HX | C38: BRICK CENTER | D38: 70545 | E38: 70546 | F38: TR01 | G38: TRANSFORMER | H38: 115 | I38: 226 | J38: 260 | K38: 271 | L38: 282 | M38: 305 | N38: 249 | O38: 282 | P38: 294 | Q38: 305 | R38: 339
B39: BRIC-TR01-230.0-115.0-15.0-HX | C39: BRICK CENTER | D39: 70545 | E39: 70546 | F39: TR01 | G39: TRANSFORMER | H39: 230 | I39: 226 | J39: 260 | K39: 271 | L39: 283 | M39: 305 | N39: 249 | O39: 283 | P39: 294 | Q39: 305 | R39: 339
B40: BRIC-TR01-230.0-115.0-15.0-HX | C40: BRICK CENTER | D40: 70545 | E40: 70546 | F40: 9971 MU B | G40: CURRENT_TRANSFORMER | H40: 115 | I40: 239 | J40: 239 | K40: 239 | L40: 239 | M40: 239 | N40: 239 | O40: 239 | P40: 239 | Q40: 239 | R40: 239
B41: BRIC-TR01-230.0-115.0-15.0-HX | C41: BRICK CENTER | D41: 70545 | E41: 70546 | F41: 9971 MU A | G41: CURRENT_TRANSFORMER | H41: 115 | I41: 239 | J41: 239 | K41: 239 | L41: 239 | M41: 239 | N41: 239 | O41: 239 | P41: 239 | Q41: 239 | R41: 239
B42: BRIC-TR01-230.0-115.0-15.0-HX | C42: BRICK CENTER | D42: 70545 | E42: 70546 | F42: 9971 | G42: BREAKER | H42: 115 | I42: 239 | J42: 239 | K42: 239 | L42: 239 | M42: 239 | N42: 239 | O42: 239 | P42: 239 | Q42: 239 | R42: 239
...

Sheet Transformer In Construction
D2: FAC-008-5 Transformer | H2: OPCO: PSC | M2: VALIDATION STATUS: VALID
H3: BES: Y | M3: LIFE CYCLE STATUS: IN CONSTRUCTION
B5: FACILITY DESIGNATION | C5: SUBSTATION | D5: HIGH SIDE PSSE | E5: LOWSIDE PSSE | F5: EQUIPMENT NAME | G5: EQUIPMENT TYPE | H5: VOLTAGE (kV) | I5: SN (MVA) | J5: SE8 (MVA) | K5: SE4 (MVA) | L5: SE2 (MVA) | M5: SE30 (MVA) | N5: WN (MVA) | O5: WE8 (MVA) | P5: WE4 (MVA) | Q5: WE2 (MVA) | R5: WE30 (MVA) | S5: COMMENTS
B6: RIDG-TR02-230.0-115.0-13.8-HX | C6: RIDGE SUBSTATION | D6: 70355 | E6: 70354 | F6: RIDG-TR02-230.0-115.0-13.8-HX | G6: FACILITY | I6: 260 | J6: 260 | K6: 305 | L6: 305 | M6: 305 | N6: 311 | O6: 311 | P6: 347 | Q6: 347 | R6: 347
B7: RIDG-TR02-230.0-115.0-13.8-HX | C7: RIDGE SUBSTATION | D7: 70355 | E7: 70354 | F7: 1000 - 61 | G7: BUSBAR_SECTION | H7: 115 | I7: 260 | J7: 260 | K7: 305 | L7: 305 | M7: 305 | N7: 311 | O7: 311 | P7: 347 | Q7: 347 | R7: 347
B8: RIDG-TR02-230.0-115.0-13.8-HX | C8: RIDGE SUBSTATION | D8: 70355 | E8: 70354 | F8: TR02 | G8: TRANSFORMER | H8: 115 | I8: 285 | J8: 327 | K8: 342 | L8: 356 | M8: 384 | N8: 313 | O8: 356 | P8: 370 | Q8: 384 | R8: 427
B9: RIDG-TR02-230.0-115.0-13.8-HX | C9: RIDGE SUBSTATION | D9: 70355 | E9: 70354 | F9: TR02 | G9: TRANSFORMER | H9: 230 | I9: 285 | J9: 327 | K9: 342 | L9: 356 | M9: 384 | N9: 313 | O9: 356 | P9: 370 | Q9: 384 | R9: 427
B10: SMOK-TR01-230.0-115.0-13.8-HX | C10: SMOKY HILL SUBSTATION | D10: 70396 | E10: 70395 | F10: SMOK-TR01-230.0-115.0-13.8-HX | G10: FACILITY | I10: 150 | J10: 173 | K10: 180 | L10: 188 | M10: 203 | N10: 165 | O10: 188 | P10: 195 | Q10: 203 | R10: 225
B11: SMOK-TR01-230.0-115.0-13.8-HX | C11: SMOKY HILL SUBSTATION | D11: 70396 | E11: 70395 | F11: TR01 | G11: TRANSFORMER | H11: 230 | I11: 150 | J11: 172 | K11: 180 | L11: 188 | M11: 203 | N11: 165 | O11: 188 | P11: 195 | Q11: 203 | R11: 225
B12: SMOK-TR01-230.0-115.0-13.8-HX | C12: SMOKY HILL SUBSTATION | D12: 70396 | E12: 70395 | F12: TR01 | G12: TRANSFORMER | H12: 115 | I12: 150 | J12: 173 | K12: 180 | L12: 187 | M12: 203 | N12: 165 | O12: 187 | P12: 195 | Q12: 203 | R12: 225
B13: SMOK-TR02-230.0-115.0-13.8-HX | C13: SMOKY HILL SUBSTATION | D13: 70396 | E13: 70395 | F13: SMOK-TR02-230.0-115.0-13.8-HX | G13: FACILITY | I13: 168 | J13: 168 | K13: 193 | L13: 202 | M13: 210 | N13: 185 | O13: 185 | P13: 210 | Q13: 218 | R13: 227
B14: SMOK-TR02-230.0-115.0-13.8-HX | C14: SMOKY HILL SUBSTATION | D14: 70396 | E14: 70395 | F14: TR02 | G14: TRANSFORMER | H14: 115 | I14: 168 | J14: 168 | K14: 193 | L14: 202 | M14: 210 | N14: 185 | O14: 185 | P14: 210 | Q14: 218 | R14: 227
B15: SMOK-TR02-230.0-115.0-13.8-HX | C15: SMOKY HILL SUBSTATION | D15: 70396 | E15: 70395 | F15: TR02 | G15: TRANSFORMER | H15: 230 | I15: 168 | J15: 168 | K15: 193 | L15: 202 | M15: 210 | N15: 185 | O15: 185 | P15: 210 | Q15: 218 | R15: 227
B16: TARR-TR01-230.0-115.0-13.8-HX | C16: TARRYALL SUBSTATION | D16: 70427 | E16: 70426 | F16: TARR-TR01-230.0-115.0-13.8-HX | G16: FACILITY | I16: 172 | J16: 198 | K16: 206 | L16: 215 | M16: 219 | N16: 189 | O16: 215 | P16: 219 | Q16: 219 | R16: 219
B17: TARR-TR01-230.0-115.0-13.8-HX | C17: TARRYALL SUBSTATION | D17: 70427 | E17: 70426 | F17: TR01 | G17: TRANSFORMER | H17: 115 | I17: 172 | J17: 198 | K17: 206 | L17: 215 | M17: 232 | N17: 189 | O17: 215 | P17: 223 | Q17: 232 | R17: 258
B18: TARR-TR01-230.0-115.0-13.8-HX | C18: TARRYALL SUBSTATION | D18: 70427 | E18: 70426 | F18: TR01 | G18: TRANSFORMER | H18: 230 | I18: 172 | J18: 198 | K18: 206 | L18: 215 | M18: 232 | N18: 189 | O18: 215 | P18: 223 | Q18: 232 | R18: 258
B19: TARR-TR01-230.0-115.0-13.8-HX | C19: TARRYALL SUBSTATION | D19: 70427 | E19: 70426 | F19: TR01 X BCT SB | G19: CURRENT_TRANSFORMER | H19: 115 | I19: 219 | J19: 219 | K19: 219 | L19: 219 | M19: 219 | N19: 219 | O19: 219 | P19: 219 | Q19: 219 | R19: 219

Sheet Lamar DC Tie
A1: LAMAR DC TIE AMBIENT ADJUSTED FACILITY EQUIPMENT RATINGS FAC-008-5
A2: REVISED 4/27/2021
A4: Element | B4: Rating | C4: Ambient Temp (°C) | D4: Ambient Temp (°F) | E4: - | F4: Limit (MW) | G4: Overload (P.U.) | H4: Comments | I4: References
A5: Inverter | B5: Normal | C5: N/A | D5: N/A | E5: - | F5: 210 | G5: N/A | I5: Section 6.1 of Main Circuit Parameters Document.
B6: Continuous Overload | C6: < 0 | D6: < 32 | E6: - | F6: =G6*$F$5 -> 252 | G6: 1.2 | H6: Overload values were interpolated from the "with out redundant cooling" line in the reference figure given by the manufacturer. | I6: Figure 2 in Section 6.3.1 of Main Main Circuit Parameters Document.
C7: 10 | D7: =(C7*9/5) + 32 -> 50 | E7: - | F7: =G7*$F$5 -> 242.45455 | G7: =1.2-(1.2-1)/(44)*C7 -> 1.1545455
C8: 20 | D8: =(C8*9/5) + 32 -> 68 | E8: - | F8: =G8*$F$5 -> 232.90909 | G8: =1.2-(1.2-1)/(44)*C8 -> 1.1090909
C9: 30 | D9: =(C9*9/5) + 32 -> 86 | E9: - | F9: =G9*$F$5 -> 223.36364 | G9: =1.2-(1.2-1)/(44)*C9 -> 1.0636364
C10: 40 | D10: =(C10*9/5) + 32 -> 104 | E10: - | F10: =G10*$F$5 -> 213.81818 | G10: =1.2-(1.2-1)/(44)*C10 -> 1.0181818
C11: 44 | D11: =(C11*9/5) + 32 -> 111.2 | E11: - | F11: =G11*$F$5 -> 210 | G11: =1.2-(1.2-1)/(44)*C11 -> 1
B12: 2 Hour Overload | C12: < 15 | D12: < 59 | E12: - | F12: =G12*$F$5 -> 252 | G12: 1.2 | H12: Overload values were interpolated from the "with out redundant cooling" line in the reference figure given by the manufacturer. | I12: Figure 3 in Section 6.3.2 of Main Main Circuit Parameters Document.
C13: 20 | D13: =(C13*9/5) + 32 -> 68 | E13: - | F13: =G13*$F$5 -> 244.75862 | G13: =1.2-(1.2-1)/(44-15)*(C13-15) -> 1.1655172
C14: 30 | D14: =(C14*9/5) + 32 -> 86 | E14: - | F14: =G14*$F$5 -> 230.27586 | G14: =1.2-(1.2-1)/(44-15)*(C14-15) -> 1.0965517
C15: 40 | D15: =(C15*9/5) + 32 -> 104 | E15: - | F15: =G15*$F$5 -> 215.7931 | G15: =1.2-(1.2-1)/(44-15)*(C15-15) -> 1.0275862
C16: 44 | D16: =(C16*9/5) + 32 -> 111.2 | E16: - | F16: =G16*$F$5 -> 210 | G16: =1.2-(1.2-1)/(44-15)*(C16-15) -> 1
A18: Element | B18: Rating | C18: Ambient Temp (°C) | D18: Ambient Temp (°F) | E18: High Side Limit (Amps) | F18: Limit (MVA) | G18: Overload (P.U.) | H18: Comments | I18: References
A19: 230kV Transformer | B19: Normal | C19: N/A | D19: N/A | E19: =1000*F19/(SQRT(3)*230) -> 564.79918 | F19: 225 | G19: N/A | I19: Transformer Nameplate
B20: Continuous Overload | C20: < 0 | D20: < 32 | E20: 713 | F20: =E20*230*SQRT(3)/1000 -> 284.03901 | G20: =E20/$E$19 -> 1.2623956 | H20: Overload values shown for the two transformers are slightly different based on the High Side Limits given by the manufacturer. | I20: Section 5.3 of Pole Control Design Specification Document
C21: 10 | D21: =(C21*9/5) + 32 -> 50 | E21: 688 | F21: =E21*230*SQRT(3)/1000 -> 274.07972 | G21: =E21/$E$19 -> 1.2181321
C22: 20 | D22: =(C22*9/5) + 32 -> 68 | E22: 664 | F22: =E22*230*SQRT(3)/1000 -> 264.5188 | G22: =E22/$E$19 -> 1.1756391
C23: 30 | D23: =(C23*9/5) + 32 -> 86 | E23: 639 | F23: =E23*230*SQRT(3)/1000 -> 254.55951 | G23: =E23/$E$19 -> 1.1313756
C24: 40 | D24: =(C24*9/5) + 32 -> 104 | E24: 615 | F24: =E24*230*SQRT(3)/1000 -> 244.99859 | G24: =E24/$E$19 -> 1.0888826
C25: 44 | D25: =(C25*9/5) + 32 -> 111.2 | E25: 605 | F25: =E25*230*SQRT(3)/1000 -> 241.01487 | G25: =E25/$E$19 -> 1.0711772
B26: 2 Hour Overload | C26: < 0 | D26: < 32 | E26: 713 | F26: =E26*230*SQRT(3)/1000 -> 284.03901 | G26: =E26/$E$19 -> 1.2623956 | H26: Overload values shown for the two transformers are slightly different based on the High Side Limits given by the manufacturer. | I26: Section 5.3 of Pole Control Design Specification Document
C27: 10 | D27: =(C27*9/5) + 32 -> 50 | E27: 713 | F27: =E27*230*SQRT(3)/1000 -> 284.03901 | G27: =E27/$E$19 -> 1.2623956
C28: 20 | D28: =(C28*9/5) + 32 -> 68 | E28: 694 | F28: =E28*230*SQRT(3)/1000 -> 276.46995 | G28: =E28/$E$19 -> 1.2287553
C29: 30 | D29: =(C29*9/5) + 32 -> 86 | E29: 657 | F29: =E29*230*SQRT(3)/1000 -> 261.7302 | G29: =E29/$E$19 -> 1.1632453
C30: 40 | D30: =(C30*9/5) + 32 -> 104 | E30: 620 | F30: =E30*230*SQRT(3)/1000 -> 246.99045 | G30: =E30/$E$19 -> 1.0977353
C31: 44 | D31: =(C31*9/5) + 32 -> 111.2 | E31: 605 | F31: =E31*230*SQRT(3)/1000 -> 241.01487 | G31: =E31/$E$19 -> 1.0711772
A33: Element | B33: Rating | C33: Ambient Temp (°C) | D33: Ambient Temp (°F) | E33: High Side Limit (Amps) | F33: Limit (MVA) | G33: Overload (P.U.) | H33: Comments | I33: References
A34: 345kV Transformer | B34: Normal | C34: N/A | D34: N/A | E34: =1000*F34/(SQRT(3)*345) -> 376.53278 | F34: 225 | G34: N/A | I34: Transformer Nameplate
B35: Continuous Overload | C35: < 0 | D35: < 32 | E35: 475 | F35: =E35*345*SQRT(3)/1000 -> 283.83983 | G35: =E35/$E$34 -> 1.2615103 | H35: Overload values shown for the two transformers are slightly different based on the High Side Limits given by the manufacturer. | I35: Section 5.3 of Pole Control Design Specification Document
C36: 10 | D36: =(C36*9/5) + 32 -> 50 | E36: 459 | F36: =E36*345*SQRT(3)/1000 -> 274.27891 | G36: =E36/$E$34 -> 1.2190174
C37: 20 | D37: =(C37*9/5) + 32 -> 68 | E37: 442 | F37: =E37*345*SQRT(3)/1000 -> 264.12043 | G37: =E37/$E$34 -> 1.1738686
C38: 30 | D38: =(C38*9/5) + 32 -> 86 | E38: 426 | F38: =E38*345*SQRT(3)/1000 -> 254.55951 | G38: =E38/$E$34 -> 1.1313756
